Workbook

Sheet C.Pagar
A1: =SUBTOTAL(2,Tabela1[NF]) -> 536 | F1: 991587.1 | G1: =SUBTOTAL(9,Tabela1[VALOR]) -> 7986006 | J1: Check NF = Descobri pelo DDA
A2: NF | B2: DT. VENCIMENTO | C2: TIPO | D2: CLASSIFICAÇÃO | E2: DESCRIÇÃO | F2: FORNECEDOR | G2: VALOR | H2: PARC. | I2: # | J2: OBSERVAÇÕES | K2: DT. PAGAMENTO | L2: Valor original | M2: Juros | P2: RESUMO
A3: 14872 | B3: 45887 | C3: Váriavel | F3: Advance Comercio de Bicicletas e Motos Eireli | G3: 1439.8 | H3: 1*3 | I3: =COUNTIF(Tabela1[NF],Tabela1[[#This Row],[NF]]) -> 3 | K3: 45887 | P3: COMISSÕES E TAXAS DOS MARKETPLACES
A4: 442577 | B4: 45903 | C4: Váriavel | D4: Peças | F4: ISAPA IMPORTAÇÃO E COMERCIO LTDA | G4: 20895.3 | H4: 1*1 | I4: =COUNTIF(Tabela1[NF],Tabela1[[#This Row],[NF]]) -> 1 | K4: =Tabela1[[#This Row],[DT. VENCIMENTO]] -> 45903 | N4: {=_xlfn.XLOOKUP(TRIM(D4),TRIM(DFC!A:A),DFC!A:A,"NÃO ESTÁ NA DFC")} -> PEÇAS | P4: Consultorias
A5: 442590 | B5: 45903 | C5: Váriavel | D5: Peças | F5: ISAPA IMPORTAÇÃO E COMERCIO LTDA | G5: 11070.67 | H5: 1*1 | I5: =COUNTIF(Tabela1[NF],Tabela1[[#This Row],[NF]]) -> 1 | K5: =Tabela1[[#This Row],[DT. VENCIMENTO]] -> 45903 | N5: {=_xlfn.XLOOKUP(TRIM(D5),TRIM(DFC!A:A),DFC!A:A,"NÃO ESTÁ NA DFC")} -> PEÇAS | P5: Contabilidade
A6: 436412 | B6: 45905 | C6: Váriavel | D6: Peças | F6: LIQUIDACAO BOLETO 61327045000160 ISAPA IMPE COML | G6: 5160.11 | H6: 2*5 | I6: =COUNTIF(Tabela1[NF],Tabela1[[#This Row],[NF]]) -> 5 | K6: 45936 | P6: Emabalagens
A7: 436358 | B7: 45905 | C7: Váriavel | D7: Peças | F7: LIQUIDACAO BOLETO 61327045000160 ISAPA IMPE COML | G7: 6117.9 | I7: =COUNTIF(Tabela1[NF],Tabela1[[#This Row],[NF]]) -> 5 | K7: =B7 -> 45905 | P7: ERP
A8: 436424 | B8: 45905 | C8: Váriavel | D8: Peças | F8: LIQUIDACAO BOLETO 61327045000160 ISAPA IMPE COML | G8: 2959.38 | I8: =COUNTIF(Tabela1[NF],Tabela1[[#This Row],[NF]]) -> 4 | K8: =Tabela1[[#This Row],[DT. VENCIMENTO]] -> 45905 | P8: Ferramentas para manutenção
A9: 436345 | B9: 45905 | C9: Váriavel | D9: Peças | F9: LIQUIDACAO BOLETO 61327045000160 ISAPA IMPE COML | G9: 51965.5 | I9: =COUNTIF(Tabela1[NF],Tabela1[[#This Row],[NF]]) -> 6 | K9: =B9 -> 45905 | P9: Frete de Saída
A10: 436655 | B10: 45906 | C10: Váriavel | D10: Peças | F10: LIQUIDACAO BOLETO 61327045000160 ISAPA INC COM L | G10: 29413.88 | I10: =COUNTIF(Tabela1[NF],Tabela1[[#This Row],[NF]]) -> 5 | K10: =Tabela1[[#This Row],[DT. VENCIMENTO]] -> 45906 | P10: Gran Residence
A11: 8043 | B11: 45908 | C11: Váriavel | F11: TWR Industria e Comercio LTDA | G11: 60502.11 | H11: 1*1 | I11: =COUNTIF(Tabela1[NF],Tabela1[[#This Row],[NF]]) -> 1 | J11: Pagamento à vista. | K11: =Tabela1[[#This Row],[DT. VENCIMENTO]] -> 45908 | P11: Internet
A12: 438008 | B12: 45912 | C12: Váriavel | D12: Peças | F12: LIQUIDACAO BOLETO 61327045000160 ISAPA IMPE COML | G12: 2850.82 | I12: =COUNTIF(Tabela1[NF],Tabela1[[#This Row],[NF]]) -> 4 | K12: =Tabela1[[#This Row],[DT. VENCIMENTO]] -> 45912 | P12: Marcas e patentes
A13: 14872 | B13: 45915 | C13: Váriavel | F13: Advance Comercio de Bicicletas e Motos Eireli | G13: 1439.8 | H13: 2*3 | I13: =COUNTIF(Tabela1[NF],Tabela1[[#This Row],[NF]]) -> 3 | K13: =Tabela1[[#This Row],[DT. VENCIMENTO]] -> 45915 | P13: Material de Escritório
A14: 8761 | B14: 45917 | C14: Váriavel | F14: Arosul Ind Comercio de Peças Eireli | G14: 563.55 | H14: 1*3 | I14: =COUNTIF(Tabela1[NF],Tabela1[[#This Row],[NF]]) -> 2 | K14: =Tabela1[[#This Row],[DT. VENCIMENTO]] -> 45917 | P14: Peças
A15: 69985 | B15: 45917 | C15: Váriavel | F15: MOLIANI E GERALDINI | G15: 697.71 | H15: 1*1 | I15: =COUNTIF(Tabela1[NF],Tabela1[[#This Row],[NF]]) -> 1 | K15: =Tabela1[[#This Row],[DT. VENCIMENTO]] -> 45917 | P15: Serviço Terceirizado
A16: 438751 | B16: 45917 | C16: Váriavel | D16: Peças | F16: LIQUIDACAO BOLETO 61327045000160 ISAPA IMPE COML | G16: 1139.28 | I16: =COUNTIF(Tabela1[NF],Tabela1[[#This Row],[NF]]) -> 4 | K16: =B16 -> 45917 | P16: T.I
A17: 12943 | B17: 45918 | C17: Váriavel | F17: THOR INDUSTRIAL LTDA | G17: 1600.32 | H17: 1*3 | I17: =COUNTIF(Tabela1[NF],Tabela1[[#This Row],[NF]]) -> 2 | K17: =Tabela1[[#This Row],[DT. VENCIMENTO]] -> 45918 | P17: Trabalhista
A18: 45901 | B18: 45920 | C18: Fixo | F18: FOLHA DE PAGAMENTO | G18: 9679.49 | H18: 1*1 | I18: =COUNTIF(Tabela1[NF],Tabela1[[#This Row],[NF]]) -> 9 | J18: Adiantamento (VALE) | K18: =Tabela1[[#This Row],[DT. VENCIMENTO]] -> 45920 | P18: 13 SALARIO
A19: 221024 | B19: 45921 | C19: Váriavel | F19: OX DA AMAZONIA IND. DE BICICLETAS S.A | G19: 2211.65 | H19: 1*6 | I19: =COUNTIF(Tabela1[NF],Tabela1[[#This Row],[NF]]) -> 2 | K19: =Tabela1[[#This Row],[DT. VENCIMENTO]] -> 45921 | P19: Acordo Judicial
A20: 1278 | B20: 45922 | C20: Váriavel | F20: Wester Bike Industria e Comercio LTDA | G20: 523.18 | H20: 1*2 | I20: =COUNTIF(Tabela1[NF],Tabela1[[#This Row],[NF]]) -> 2 | K20: =Tabela1[[#This Row],[DT. VENCIMENTO]] -> 45922 | P20: Adiantamento Salarial
A21: 3568 | B21: 45924 | C21: Váriavel | F21: SAAR ADESIVOS | G21: 6996.9 | H21: 1*5 | I21: =COUNTIF(Tabela1[NF],Tabela1[[#This Row],[NF]]) -> 3 | J21: N.C.K - INDUSTRIAL | K21: =Tabela1[[#This Row],[DT. VENCIMENTO]] -> 45924 | P21: Alimentação
A22: 7341 | B22: 45925 | C22: Váriavel | F22: FLAY INDUSTRIA E COMERCIO LTDA | G22: 281.52 | H22: 3*3 | I22: =COUNTIF(Tabela1[NF],Tabela1[[#This Row],[NF]]) -> 1 | K22: =Tabela1[[#This Row],[DT. VENCIMENTO]] -> 45925 | P22: Aluguel
A23: 120785 | B23: 45925 | C23: Váriavel | F23: Kalf Ind Com Plasticos LTDA | G23: 1908.61 | H23: 2*2 | I23: =COUNTIF(Tabela1[NF],Tabela1[[#This Row],[NF]]) -> 1 | K23: =Tabela1[[#This Row],[DT. VENCIMENTO]] -> 45925 | P23: Alvará
A24: 162321 | B24: 45925 | C24: Váriavel | F24: BRAS ONDA PAPELÃO ONDULADO LTDA | G24: 3311.57 | H24: 3*3 | I24: =COUNTIF(Tabela1[NF],Tabela1[[#This Row],[NF]]) -> 1 | K24: =Tabela1[[#This Row],[DT. VENCIMENTO]] -> 45925 | P24: Amortização Felipe
A25: 7881 | B25: 45926 | C25: Váriavel | F25: FLAY INDUSTRIA E COMERCIO LTDA | G25: 269.16 | H25: 1*3 | I25: =COUNTIF(Tabela1[NF],Tabela1[[#This Row],[NF]]) -> 2 | K25: =Tabela1[[#This Row],[DT. VENCIMENTO]] -> 45926 | P25: anymarket mensalidade
A26: 7921 | B26: 45926 | C26: Váriavel | F26: FLAY INDUSTRIA E COMERCIO LTDA | G26: 7134.45 | H26: 1*3 | I26: =COUNTIF(Tabela1[NF],Tabela1[[#This Row],[NF]]) -> 2 | K26: =Tabela1[[#This Row],[DT. VENCIMENTO]] -> 45926 | N26: {=_xlfn.XLOOKUP(TRIM(D26),TRIM(DFC!A:A),DFC!A:A,"NÃO ESTÁ NA DFC")} -> 0 | P26: anymarket taxas
A27: 2879 | B27: 45927 | C27: Váriavel | F27: AD Flex Etiquetas Eireli | G27: 440 | H27: 1*1 | I27: =COUNTIF(Tabela1[NF],Tabela1[[#This Row],[NF]]) -> 1 | K27: 45929 | N27: {=_xlfn.XLOOKUP(TRIM(D27),TRIM(DFC!A:A),DFC!A:A,"NÃO ESTÁ NA DFC")} -> 0 | P27: CFR
A28: 143402 | B28: 45927 | C28: Váriavel | F28: JULIO ANDÓ | G28: 2555.63 | H28: 4*4 | I28: =COUNTIF(Tabela1[NF],Tabela1[[#This Row],[NF]]) -> 1 | K28: 45929 | P28: Combustível
A29: 155144 | B29: 45927 | C29: Váriavel | F29: JULIO ANDÓ | G29: 8542.83 | H29: 1*1 | I29: =COUNTIF(Tabela1[NF],Tabela1[[#This Row],[NF]]) -> 1 | K29: 45929 | P29: COMISSÕES E TAXAS DOS MARKETPLACES
A30: 1928 | B30: 45928 | C30: Váriavel | F30: GUIDON BIKE PEÇAS PARA BICICLETAS IND E COM EIRELI | G30: 1180.64 | H30: 3*3 | I30: =COUNTIF(Tabela1[NF],Tabela1[[#This Row],[NF]]) -> 1 | K30: 45929 | P30: Compra de máquina
A31: 7266 | B31: 45928 | C31: Váriavel | F31: GUIDON BIKE PEÇAS PARA BICICLETAS IND E COM EIRELI | G31: 505.99 | H31: 3*3 | I31: =COUNTIF(Tabela1[NF],Tabela1[[#This Row],[NF]]) -> 1 | K31: 45929 | P31: Compra de Móveis e Utensílios
A32: 152744 | B32: 45928 | C32: Váriavel | F32: JULIO ANDÓ | G32: 1616.98 | H32: 1*5 | I32: =COUNTIF(Tabela1[NF],Tabela1[[#This Row],[NF]]) -> 2 | K32: 45929 | N32: {=_xlfn.XLOOKUP(TRIM(D32),TRIM(DFC!A:A),DFC!A:A,"NÃO ESTÁ NA DFC")} -> 0 | P32: Confraternização
A33: 614512 | B33: 45928 | C33: Váriavel | D33: Peças | F33: ISAPA IMPORTAÇÃO E COMERCIO LTDA | G33: 3359.95 | H33: 1*5 | I33: =COUNTIF(Tabela1[NF],Tabela1[[#This Row],[NF]]) -> 5 | K33: 45929 | N33: {=_xlfn.XLOOKUP(TRIM(D33),TRIM(DFC!A:A),DFC!A:A,"NÃO ESTÁ NA DFC")} -> PEÇAS | P33: Copel
A34: 614562 | B34: 45928 | C34: Váriavel | D34: Peças | F34: ISAPA IMPORTAÇÃO E COMERCIO LTDA | G34: 2768.5 | H34: 1*5 | I34: =COUNTIF(Tabela1[NF],Tabela1[[#This Row],[NF]]) -> 5 | K34: 45929 | N34: {=_xlfn.XLOOKUP(TRIM(D34),TRIM(DFC!A:A),DFC!A:A,"NÃO ESTÁ NA DFC")} -> PEÇAS | P34: Desp de Marketing e Propaganda
A35: 3974 | B35: 45929 | C35: Váriavel | F35: FLAY INDUSTRIA E COMERCIO LTDA | G35: 9001.622 | H35: 1*3 | I35: =COUNTIF(Tabela1[NF],Tabela1[[#This Row],[NF]]) -> 2 | K35: 45929 | N35: {=_xlfn.XLOOKUP(TRIM(D35),TRIM(DFC!A:A),DFC!A:A,"NÃO ESTÁ NA DFC")} -> 0 | P35: Detran
A36: 7373 | B36: 45929 | C36: Váriavel | F36: FLAY INDUSTRIA E COMERCIO LTDA | G36: 3793.65 | H36: 3*3 | I36: =COUNTIF(Tabela1[NF],Tabela1[[#This Row],[NF]]) -> 1 | K36: 45929 | N36: {=_xlfn.XLOOKUP(TRIM(D36),TRIM(DFC!A:A),DFC!A:A,"NÃO ESTÁ NA DFC")} -> 0 | P36: Diária
A37: 7374 | B37: 45929 | C37: Váriavel | F37: FLAY INDUSTRIA E COMERCIO LTDA | G37: 281.52 | H37: 3*3 | I37: =COUNTIF(Tabela1[NF],Tabela1[[#This Row],[NF]]) -> 1 | K37: 45929 | N37: {=_xlfn.XLOOKUP(TRIM(D37),TRIM(DFC!A:A),DFC!A:A,"NÃO ESTÁ NA DFC")} -> 0 | P37: Diárias
A38: 7614 | B38: 45929 | C38: Váriavel | F38: FLAY INDUSTRIA E COMERCIO LTDA | G38: 563.04 | H38: 2*3 | I38: =COUNTIF(Tabela1[NF],Tabela1[[#This Row],[NF]]) -> 2 | K38: 45929 | N38: {=_xlfn.XLOOKUP(TRIM(D38),TRIM(DFC!A:A),DFC!A:A,"NÃO ESTÁ NA DFC")} -> 0 | P38: Empilhadeira
A39: 7976 | B39: 45929 | C39: Váriavel | F39: FLAY INDUSTRIA E COMERCIO LTDA | G39: 9001.62 | H39: 1*3 | I39: =COUNTIF(Tabela1[NF],Tabela1[[#This Row],[NF]]) -> 1 | J39: Checar NF | K39: 45929 | N39: {=_xlfn.XLOOKUP(TRIM(D39),TRIM(DFC!A:A),DFC!A:A,"NÃO ESTÁ NA DFC")} -> 0 | P39: Equipamentos de Informática
A40: 121102 | B40: 45929 | C40: Váriavel | F40: Kalf Ind Com Plasticos LTDA | G40: 2403.44 | H40: 1*2 | I40: =COUNTIF(Tabela1[NF],Tabela1[[#This Row],[NF]]) -> 2 | K40: 45929 | N40: {=_xlfn.XLOOKUP(TRIM(D40),TRIM(DFC!A:A),DFC!A:A,"NÃO ESTÁ NA DFC")} -> 0 | P40: FGTS
...

Sheet COMPROMISSOS
B1: Inclusão | C1: Conclusão | D1: Responsáveis | E1: Gravidade | F1: TOD - Tarefa Operacional Diária (COMPROMISSOS) | G1: Descrição da Solução
A2: TRUE | B2: 46096 | C2: 46096 | D2: Matheus e Eduardo | F2: Apresentação da DRE de fev/26 | G2: Documento enviado
A3: TRUE | B3: 46097 | C3: 46097 | D3: Mateus | F3: Encerramento do contrato do barracão da Juriti Vermelha R$ 6.770,00 | G3: Entrega das chaves
A4: TRUE | B4: 46097 | C4: 46098 | D4: Matheus e Eduardo | F4: Análise de currículos para contratações | G4: Análise realizada
A5: TRUE | B5: 46097 | C5: 46104 | D5: Matheus e Eduardo | F5: Contratação compras e contas a pagar | G5: Contratada Gabriela Fernanda
A6: TRUE | B6: 46097 | C6: 46106 | D6: Vinícius | F6: Gravação Luan Pereira | G6: Gravação realizada
A7: TRUE | B7: 46097 | C7: 46106 | D7: Matheus | F7: Contratação aux. estoque | G7: Em teste
A8: TRUE | B8: 46097 | C8: 46108 | D8: Mateus | F8: Tick Tock a receber - Verificar conta corrente de recebimento | G8: ok. Recebimento PIX 27415911000136 Bytedance Brasil
A9: TRUE | B9: 46097 | C9: 46108 | D9: Matheus | F9: Verificar se o aluguel do barracão da Juriti Vermelha saiu, ou não aparece mais no DDA | G9: Aluguel Juriti Vermelha saiu do DDA
A10: TRUE | B10: 46107 | C10: 46113 | D10: Matheus e Eduardo | F10: Fluxo de caixa de março | G10: Positivo em R$ 44.402,94
A11: TRUE | B11: 46199 | C11: 46113 | D11: Mateus | F11: Definir Metas para abril/2026 | G11: Faturamento R$ 1.500.000,00, 2130 bikes
A12: TRUE | B12: 46097 | C12: 46114 | D12: Matheus | F12: Demissões | G12: Meire - OK
A13: TRUE | B13: 46097 | C13: 46114 | D13: Matheus | F13: Eliminar acessos do Lucas Landim | G13: Acessos eliminados
A14: TRUE | B14: 46097 | C14: 46121 | D14: Matheus e Eduardo | F14: Contratação contas a receber | G14: Poliana
A15: FALSE | B15: 46097 | C15: 46127 | D15: Mateus | F15: Lançamento Luan Pereira
A16: FALSE | B16: 46097 | F16: Analisar/limpar DDA - análise conta por conta (conciliação)
A17: FALSE | B17: 46097 | D17: Matheus e Eduardo | F17: Análise das contas pagar da DFC - contas analíticas
A18: FALSE | B18: 46097 | D18: Mateus e Ana | F18: Conferência nas plataformas sobre as entregas dos pedidos para liberarmos os recebimentos
A19: FALSE | B19: 46097 | D19: Mateus | F19: Definir estoque mínimo de peças
A20: FALSE | B20: 46097 | D20: Mateus | F20: Encerrar BR1 China Link do Brasil R$ 1.600,00
A21: FALSE | B21: 46107 | F21: Margem de contribuição por produto
A22: FALSE | B22: 46097 | F22: POPs, controles, indicadores
A23: FALSE | B23: 46097 | D23: Matheus | F23: Possíveis lançamentos duplicados da Prefeitura Municipal de Arapongas no DDA | G23: Verificando
A24: FALSE | B24: 46107 | F24: Projeção de compras abril
A25: FALSE | B25: 46107 | F25: Projeção de vendas abril
A26: FALSE | B26: 46107 | F26: Recebimentos e contas a receber (processo)
A27: FALSE | B27: 46097 | D27: Matheus | F27: Resumo mensal sempre atualizado diariamente do recebimento apontado no extrato Sicredi. Recebimento por canal.
A28: FALSE | B28: 46097 | D28: Matheus e Eduardo | F28: Solução envio de xmls para o Escritório (manual e domínio) - Fiscal.
A29: FALSE | B29: 46107 | D29: Mateus e Matheus | F29: Projeção de impostos competência março
A30: FALSE | B30: 46107 | D30: Mateus | F30: Redução de custos - análise de possibilidades
A31: FALSE | B31: 46107 | D31: Vinícius | F31: Marketing e lives - análise março e planejamento de abril
A32: FALSE | B32: 46107 | D32: Mateus e Matheus | F32: Cheques devolvidos e protestos (controle de contas a pagar)
A33: FALSE | B33: 45015 | D33: Matheus | F33: Análise da reimplantação do sistema ERP
A34: FALSE | B34: 46111 | D34: Matheus | F34: Levantamento de impostos e taxas em atraso
A35: FALSE | B35: 46111 | F35: Lançamento de contas no DDA (muitas contas não estão lá)
A36: FALSE | B36: 46111 | F36: Controle de devoluções e avarias
A37: FALSE | B37: 46111 | F37: Lançar todas as contas a pagar possíveis no DDA
A38: FALSE | B38: 46119 | F38: Transferir todos os funcionários de CNPJ (nova empresa)
A39: FALSE | B39: 46119 | F39: Precificação e custos
A40: FALSE
...

Sheet DDA
A1: 9 | D1: =SUM(D3:D496) -> 2346138 | F1: Mês | G1: 04 | I1: =TEXT(DATE(YEAR(TODAY()),G1,1),"mmmm") -> abril | K1: Mês | L1: 05 | N1: =TEXT(DATE(YEAR(TODAY()),L1,1),"mmmm") -> maio | P1: Mês | Q1: 06 | S1: =TEXT(DATE(YEAR(TODAY()),Q1,1),"mmmm") -> junho | U1: Mês | V1: 07 | X1: =TEXT(DATE(YEAR(TODAY()),V1,1),"mmmm") -> julho | Z1: OUTROS | AA1: =D1-SUM(AA2:AA6) -> 1790949.5
A2: Beneficiário | B2: Nº Doc | C2: Vencto | D2: Valor (R$) | F2: Ano | G2: 2026 | I2: DDA | K2: Ano | L2: 2026 | N2: DDA | P2: Ano | Q2: 2026 | S2: DDA | U2: Ano | V2: 2026 | X2: DDA | Z2: ZOEMAQ INDUSTRIA E COMERCIO DE MAQUINAS LTDA | AA2: =SUMIF(A:A,Z2,D:D) -> 479125.35
A3: JULIO ANDO CIA LTDA | B3: 164721 8 | C3: 46143 | D3: 2911.3 | F3: Dia | G3: Data | H3: Sem | I3: =SUM(I4:I34) -> 0 | K3: Dia | L3: Data | M3: Sem | N3: =SUM(N4:N34) -> 704328.16 | P3: Dia | Q3: Data | R3: Sem | S3: =SUM(S4:S34) -> 559369.71 | U3: Dia | V3: Data | W3: Sem | X3: =SUM(X4:X34) -> 436626.3 | Z3: ESCRITORIO GESTOR CONTABILIDADE LTDA | AA3: =SUMIF(A:A,Z3,D:D) -> 31952
A4: SOLUTIKA TECNOLOGIA LTDA | B4: 20722 | C4: 46143 | D4: 901.91 | F4: 01 | G4: =_xlfn.CONCAT(F4,"/",$G$1,"/",$G$2) -> 01/04/2026 | H4: =TEXT(G4,"ddd") -> qua | I4: =SUMIF(C:C,G4,D:D) -> 0 | K4: 01 | L4: =_xlfn.CONCAT(K4,"/",$L$1,"/",$L$2) -> 01/05/2026 | M4: =TEXT(L4,"ddd") -> sex | N4: =SUMIF(C:C,L4,D:D) -> 18253.52 | P4: 01 | Q4: =_xlfn.CONCAT(P4,"/",$Q$1,"/",$Q$2) -> 01/06/2026 | R4: =TEXT(Q4,"ddd") -> seg | S4: =SUMIF(C:C,Q4,D:D) -> 24267.9 | U4: 01 | V4: =_xlfn.CONCAT(U4,"/",$V$1,"/",$V$2) -> 01/07/2026 | W4: =TEXT(V4,"ddd") -> qua | X4: =SUMIF(C:C,V4,D:D) -> 22161.14 | Z4: GRAN RESIDENCE INCORPORADORA LTDA | AA4: =SUMIF(A:A,Z4,D:D) -> 6202.11
A5: VEGA DISTRIBUIDORA LTDA | B5: 24401 | C5: 46143 | D5: 4342.96 | F5: 02 | G5: =_xlfn.CONCAT(F5,"/",$G$1,"/",$G$2) -> 02/04/2026 | H5: =TEXT(G5,"ddd") -> qui | I5: =SUMIF(C:C,G5,D:D) -> 0 | K5: 02 | L5: =_xlfn.CONCAT(K5,"/",$L$1,"/",$L$2) -> 02/05/2026 | M5: =TEXT(L5,"ddd") -> sáb | N5: =SUMIF(C:C,L5,D:D) -> 36101.65 | P5: 02 | Q5: =_xlfn.CONCAT(P5,"/",$Q$1,"/",$Q$2) -> 02/06/2026 | R5: =TEXT(Q5,"ddd") -> ter | S5: =SUMIF(C:C,Q5,D:D) -> 3403.76 | U5: 02 | V5: =_xlfn.CONCAT(U5,"/",$V$1,"/",$V$2) -> 02/07/2026 | W5: =TEXT(V5,"ddd") -> qui | X5: =SUMIF(C:C,V5,D:D) -> 3403.76 | Z5: PM DE ARAPONGAS | AA5: =SUMIF(A:A,Z5,D:D) -> 9109.04
A6: M A F COM DE ARTIGOS DE PAPELA | B6: 123302 | C6: 46143 | D6: 63.3 | F6: 03 | G6: =_xlfn.CONCAT(F6,"/",$G$1,"/",$G$2) -> 03/04/2026 | H6: =TEXT(G6,"ddd") -> sex | I6: =SUMIF(C:C,G6,D:D) -> 0 | K6: 03 | L6: =_xlfn.CONCAT(K6,"/",$L$1,"/",$L$2) -> 03/05/2026 | M6: =TEXT(L6,"ddd") -> dom | N6: =SUMIF(C:C,L6,D:D) -> 5446.92 | P6: 03 | Q6: =_xlfn.CONCAT(P6,"/",$Q$1,"/",$Q$2) -> 03/06/2026 | R6: =TEXT(Q6,"ddd") -> qua | S6: =SUMIF(C:C,Q6,D:D) -> 0 | U6: 03 | V6: =_xlfn.CONCAT(U6,"/",$V$1,"/",$V$2) -> 03/07/2026 | W6: =TEXT(V6,"ddd") -> sex | X6: =SUMIF(C:C,V6,D:D) -> 0 | Z6: CEFAS S NOBRE | AA6: =SUMIF(A:A,Z6,D:D) -> 28800
A7: JULIO ANDO CIA LTDA | B7: 176542 1 | C7: 46143 | D7: 5089.31 | F7: 04 | G7: =_xlfn.CONCAT(F7,"/",$G$1,"/",$G$2) -> 04/04/2026 | H7: =TEXT(G7,"ddd") -> sáb | I7: =SUMIF(C:C,G7,D:D) -> 0 | K7: 04 | L7: =_xlfn.CONCAT(K7,"/",$L$1,"/",$L$2) -> 04/05/2026 | M7: =TEXT(L7,"ddd") -> seg | N7: =SUMIF(C:C,L7,D:D) -> 6159.42 | P7: 04 | Q7: =_xlfn.CONCAT(P7,"/",$Q$1,"/",$Q$2) -> 04/06/2026 | R7: =TEXT(Q7,"ddd") -> qui | S7: =SUMIF(C:C,Q7,D:D) -> 8774.37 | U7: 04 | V7: =_xlfn.CONCAT(U7,"/",$V$1,"/",$V$2) -> 04/07/2026 | W7: =TEXT(V7,"ddd") -> sáb | X7: =SUMIF(C:C,V7,D:D) -> 0 | Z7: TOTAL A PAGAR DDA | AA7: =SUM(AA1:AA6) -> 2346138
A8: ISAPA IMP.E COM.LTDA. | B8: 48676901 | C8: 46143 | D8: 4944.74 | F8: 05 | G8: =_xlfn.CONCAT(F8,"/",$G$1,"/",$G$2) -> 05/04/2026 | H8: =TEXT(G8,"ddd") -> dom | I8: =SUMIF(C:C,G8,D:D) -> 0 | K8: 05 | L8: =_xlfn.CONCAT(K8,"/",$L$1,"/",$L$2) -> 05/05/2026 | M8: =TEXT(L8,"ddd") -> ter | N8: =SUMIF(C:C,L8,D:D) -> 12045.74 | P8: 05 | Q8: =_xlfn.CONCAT(P8,"/",$Q$1,"/",$Q$2) -> 05/06/2026 | R8: =TEXT(Q8,"ddd") -> sex | S8: =SUMIF(C:C,Q8,D:D) -> 431.2 | U8: 05 | V8: =_xlfn.CONCAT(U8,"/",$V$1,"/",$V$2) -> 05/07/2026 | W8: =TEXT(V8,"ddd") -> dom | X8: =SUMIF(C:C,V8,D:D) -> 431.2
A9: JULIO ANDO CIA LTDA | B9: 163115 5 | C9: 46144 | D9: 19184.13 | F9: 06 | G9: =_xlfn.CONCAT(F9,"/",$G$1,"/",$G$2) -> 06/04/2026 | H9: =TEXT(G9,"ddd") -> seg | I9: =SUMIF(C:C,G9,D:D) -> 0 | K9: 06 | L9: =_xlfn.CONCAT(K9,"/",$L$1,"/",$L$2) -> 06/05/2026 | M9: =TEXT(L9,"ddd") -> qua | N9: =SUMIF(C:C,L9,D:D) -> 10715.92 | P9: 06 | Q9: =_xlfn.CONCAT(P9,"/",$Q$1,"/",$Q$2) -> 06/06/2026 | R9: =TEXT(Q9,"ddd") -> sáb | S9: =SUMIF(C:C,Q9,D:D) -> 54327.07 | U9: 06 | V9: =_xlfn.CONCAT(U9,"/",$V$1,"/",$V$2) -> 06/07/2026 | W9: =TEXT(V9,"ddd") -> seg | X9: =SUMIF(C:C,V9,D:D) -> 39507.91
A10: JR COMERCIO B ACESSORIOS LTDA | B10: 174646 1 | C10: 46144 | D10: 10842 | F10: 07 | G10: =_xlfn.CONCAT(F10,"/",$G$1,"/",$G$2) -> 07/04/2026 | H10: =TEXT(G10,"ddd") -> ter | I10: =SUMIF(C:C,G10,D:D) -> 0 | K10: 07 | L10: =_xlfn.CONCAT(K10,"/",$L$1,"/",$L$2) -> 07/05/2026 | M10: =TEXT(L10,"ddd") -> qui | N10: =SUMIF(C:C,L10,D:D) -> 56973.62 | P10: 07 | Q10: =_xlfn.CONCAT(P10,"/",$Q$1,"/",$Q$2) -> 07/06/2026 | R10: =TEXT(Q10,"ddd") -> dom | S10: =SUMIF(C:C,Q10,D:D) -> 8647.35 | U10: 07 | V10: =_xlfn.CONCAT(U10,"/",$V$1,"/",$V$2) -> 07/07/2026 | W10: =TEXT(V10,"ddd") -> ter | X10: =SUMIF(C:C,V10,D:D) -> 2504.62 | Z10: DDA | AA10: =I1 -> abril
A11: J A GOMES DE SOUZA | B11: 126011 | C11: 46144 | D11: 1628 | F11: 08 | G11: =_xlfn.CONCAT(F11,"/",$G$1,"/",$G$2) -> 08/04/2026 | H11: =TEXT(G11,"ddd") -> qua | I11: =SUMIF(C:C,G11,D:D) -> 0 | K11: 08 | L11: =_xlfn.CONCAT(K11,"/",$L$1,"/",$L$2) -> 08/05/2026 | M11: =TEXT(L11,"ddd") -> sex | N11: =SUMIF(C:C,L11,D:D) -> 10213.48 | P11: 08 | Q11: =_xlfn.CONCAT(P11,"/",$Q$1,"/",$Q$2) -> 08/06/2026 | R11: =TEXT(Q11,"ddd") -> seg | S11: =SUMIF(C:C,Q11,D:D) -> 24412.01 | U11: 08 | V11: =_xlfn.CONCAT(U11,"/",$V$1,"/",$V$2) -> 08/07/2026 | W11: =TEXT(V11,"ddd") -> qua | X11: =SUMIF(C:C,V11,D:D) -> 15778.66
A12: JHC COM DE PECAS E ACESS P BICICLETAS LTDA | B12: 112641 | C12: 46144 | D12: 3941.28 | F12: 09 | G12: =_xlfn.CONCAT(F12,"/",$G$1,"/",$G$2) -> 09/04/2026 | H12: =TEXT(G12,"ddd") -> qui | I12: =SUMIF(C:C,G12,D:D) -> 0 | K12: 09 | L12: =_xlfn.CONCAT(K12,"/",$L$1,"/",$L$2) -> 09/05/2026 | M12: =TEXT(L12,"ddd") -> sáb | N12: =SUMIF(C:C,L12,D:D) -> 15920.81 | P12: 09 | Q12: =_xlfn.CONCAT(P12,"/",$Q$1,"/",$Q$2) -> 09/06/2026 | R12: =TEXT(Q12,"ddd") -> ter | S12: =SUMIF(C:C,Q12,D:D) -> 19814 | U12: 09 | V12: =_xlfn.CONCAT(U12,"/",$V$1,"/",$V$2) -> 09/07/2026 | W12: =TEXT(V12,"ddd") -> qui | X12: =SUMIF(C:C,V12,D:D) -> 22391.24
A13: ISAPA IMP.E COM.LTDA. | B13: 48710901 | C13: 46144 | D13: 506.24 | F13: 10 | G13: =_xlfn.CONCAT(F13,"/",$G$1,"/",$G$2) -> 10/04/2026 | H13: =TEXT(G13,"ddd") -> sex | I13: =SUMIF(C:C,G13,D:D) -> 0 | K13: 10 | L13: =_xlfn.CONCAT(K13,"/",$L$1,"/",$L$2) -> 10/05/2026 | M13: =TEXT(L13,"ddd") -> dom | N13: =SUMIF(C:C,L13,D:D) -> 26826.11 | P13: 10 | Q13: =_xlfn.CONCAT(P13,"/",$Q$1,"/",$Q$2) -> 10/06/2026 | R13: =TEXT(Q13,"ddd") -> qua | S13: =SUMIF(C:C,Q13,D:D) -> 26914.8 | U13: 10 | V13: =_xlfn.CONCAT(U13,"/",$V$1,"/",$V$2) -> 10/07/2026 | W13: =TEXT(V13,"ddd") -> sex | X13: =SUMIF(C:C,V13,D:D) -> 25065.28 | Z13: Saldo a Pagar | AA13: =I3 -> 0
A14: JULIO ANDO CIA LTDA | B14: 163170 5 | C14: 46145 | D14: 1933.39 | F14: 11 | G14: =_xlfn.CONCAT(F14,"/",$G$1,"/",$G$2) -> 11/04/2026 | H14: =TEXT(G14,"ddd") -> sáb | I14: =SUMIF(C:C,G14,D:D) -> 0 | K14: 11 | L14: =_xlfn.CONCAT(K14,"/",$L$1,"/",$L$2) -> 11/05/2026 | M14: =TEXT(L14,"ddd") -> seg | N14: =SUMIF(C:C,L14,D:D) -> 28818.24 | P14: 11 | Q14: =_xlfn.CONCAT(P14,"/",$Q$1,"/",$Q$2) -> 11/06/2026 | R14: =TEXT(Q14,"ddd") -> qui | S14: =SUMIF(C:C,Q14,D:D) -> 7281.22 | U14: 11 | V14: =_xlfn.CONCAT(U14,"/",$V$1,"/",$V$2) -> 11/07/2026 | W14: =TEXT(V14,"ddd") -> sáb | X14: =SUMIF(C:C,V14,D:D) -> 2082.12
A15: LUMASA EMBALAGENS LTDA | B15: 505-2 | C15: 46145 | D15: 3513.53 | F15: 12 | G15: =_xlfn.CONCAT(F15,"/",$G$1,"/",$G$2) -> 12/04/2026 | H15: =TEXT(G15,"ddd") -> dom | I15: =SUMIF(C:C,G15,D:D) -> 0 | K15: 12 | L15: =_xlfn.CONCAT(K15,"/",$L$1,"/",$L$2) -> 12/05/2026 | M15: =TEXT(L15,"ddd") -> ter | N15: =SUMIF(C:C,L15,D:D) -> 12917.25 | P15: 12 | Q15: =_xlfn.CONCAT(P15,"/",$Q$1,"/",$Q$2) -> 12/06/2026 | R15: =TEXT(Q15,"ddd") -> sex | S15: =SUMIF(C:C,Q15,D:D) -> 7439.9 | U15: 12 | V15: =_xlfn.CONCAT(U15,"/",$V$1,"/",$V$2) -> 12/07/2026 | W15: =TEXT(V15,"ddd") -> dom | X15: =SUMIF(C:C,V15,D:D) -> 502.29
A16: FLAY INDUSTRIA E COMERCIO LTDA | B16: 5221 - 1 | C16: 46146 | D16: 2654.51 | F16: 13 | G16: =_xlfn.CONCAT(F16,"/",$G$1,"/",$G$2) -> 13/04/2026 | H16: =TEXT(G16,"ddd") -> seg | I16: =SUMIF(C:C,G16,D:D) -> 0 | K16: 13 | L16: =_xlfn.CONCAT(K16,"/",$L$1,"/",$L$2) -> 13/05/2026 | M16: =TEXT(L16,"ddd") -> qua | N16: =SUMIF(C:C,L16,D:D) -> 7774.67 | P16: 13 | Q16: =_xlfn.CONCAT(P16,"/",$Q$1,"/",$Q$2) -> 13/06/2026 | R16: =TEXT(Q16,"ddd") -> sáb | S16: =SUMIF(C:C,Q16,D:D) -> 6558.66 | U16: 13 | V16: =_xlfn.CONCAT(U16,"/",$V$1,"/",$V$2) -> 13/07/2026 | W16: =TEXT(V16,"ddd") -> seg | X16: =SUMIF(C:C,V16,D:D) -> 9180.53
A17: ISAPA IMP.E COM.LTDA. | B17: 489350 | C17: 46146 | D17: 3504.91 | F17: 14 | G17: =_xlfn.CONCAT(F17,"/",$G$1,"/",$G$2) -> 14/04/2026 | H17: =TEXT(G17,"ddd") -> ter | I17: =SUMIF(C:C,G17,D:D) -> 0 | K17: 14 | L17: =_xlfn.CONCAT(K17,"/",$L$1,"/",$L$2) -> 14/05/2026 | M17: =TEXT(L17,"ddd") -> qui | N17: =SUMIF(C:C,L17,D:D) -> 7468.85 | P17: 14 | Q17: =_xlfn.CONCAT(P17,"/",$Q$1,"/",$Q$2) -> 14/06/2026 | R17: =TEXT(Q17,"ddd") -> dom | S17: =SUMIF(C:C,Q17,D:D) -> 38173.42 | U17: 14 | V17: =_xlfn.CONCAT(U17,"/",$V$1,"/",$V$2) -> 14/07/2026 | W17: =TEXT(V17,"ddd") -> ter | X17: =SUMIF(C:C,V17,D:D) -> 40160.93 | Z17: OUTROS | AA17: 1173693.2
A18: NEW BOX EMBALAGENS | B18: 30675 002 | C18: 46147 | D18: 3906.98 | F18: 15 | G18: =_xlfn.CONCAT(F18,"/",$G$1,"/",$G$2) -> 15/04/2026 | H18: =TEXT(G18,"ddd") -> qua | I18: =SUMIF(C:C,G18,D:D) -> 0 | K18: 15 | L18: =_xlfn.CONCAT(K18,"/",$L$1,"/",$L$2) -> 15/05/2026 | M18: =TEXT(L18,"ddd") -> sex | N18: =SUMIF(C:C,L18,D:D) -> 48103.74 | P18: 15 | Q18: =_xlfn.CONCAT(P18,"/",$Q$1,"/",$Q$2) -> 15/06/2026 | R18: =TEXT(Q18,"ddd") -> seg | S18: =SUMIF(C:C,Q18,D:D) -> 32191.7 | U18: 15 | V18: =_xlfn.CONCAT(U18,"/",$V$1,"/",$V$2) -> 15/07/2026 | W18: =TEXT(V18,"ddd") -> qua | X18: =SUMIF(C:C,V18,D:D) -> 15838.32 | Z18: ZOEMAQ INDUSTRIA E COMERCIO DE MAQUINAS LTDA | AA18: 495096.19
A19: FLAY INDUSTRIA E COMERCIO LTDA | B19: 5226 - 1 | C19: 46147 | D19: 4288.74 | F19: 16 | G19: =_xlfn.CONCAT(F19,"/",$G$1,"/",$G$2) -> 16/04/2026 | H19: =TEXT(G19,"ddd") -> qui | I19: =SUMIF(C:C,G19,D:D) -> 0 | K19: 16 | L19: =_xlfn.CONCAT(K19,"/",$L$1,"/",$L$2) -> 16/05/2026 | M19: =TEXT(L19,"ddd") -> sáb | N19: =SUMIF(C:C,L19,D:D) -> 33750.5 | P19: 16 | Q19: =_xlfn.CONCAT(P19,"/",$Q$1,"/",$Q$2) -> 16/06/2026 | R19: =TEXT(Q19,"ddd") -> ter | S19: =SUMIF(C:C,Q19,D:D) -> 3087.61 | U19: 16 | V19: =_xlfn.CONCAT(U19,"/",$V$1,"/",$V$2) -> 16/07/2026 | W19: =TEXT(V19,"ddd") -> qui | X19: =SUMIF(C:C,V19,D:D) -> 1100.43 | Z19: ESCRITORIO GESTOR CONTABILIDADE LTDA | AA19: 35946
A20: WESTER BIKE INDUSTRIA E COMERCIO LTDA | B20: 00002499/1 | C20: 46147 | D20: 707.16 | F20: 17 | G20: =_xlfn.CONCAT(F20,"/",$G$1,"/",$G$2) -> 17/04/2026 | H20: =TEXT(G20,"ddd") -> sex | I20: =SUMIF(C:C,G20,D:D) -> 0 | K20: 17 | L20: =_xlfn.CONCAT(K20,"/",$L$1,"/",$L$2) -> 17/05/2026 | M20: =TEXT(L20,"ddd") -> dom | N20: =SUMIF(C:C,L20,D:D) -> 1100.11 | P20: 17 | Q20: =_xlfn.CONCAT(P20,"/",$Q$1,"/",$Q$2) -> 17/06/2026 | R20: =TEXT(Q20,"ddd") -> qua | S20: =SUMIF(C:C,Q20,D:D) -> 11429.64 | U20: 17 | V20: =_xlfn.CONCAT(U20,"/",$V$1,"/",$V$2) -> 17/07/2026 | W20: =TEXT(V20,"ddd") -> sex | X20: =SUMIF(C:C,V20,D:D) -> 0 | Z20: GRAN RESIDENCE INCORPORADORA LTDA | AA20: 8269.48
A21: LEGACY MONITORAMENTO LTDA | B21: 46025 | C21: 46147 | D21: 144.56 | F21: 18 | G21: =_xlfn.CONCAT(F21,"/",$G$1,"/",$G$2) -> 18/04/2026 | H21: =TEXT(G21,"ddd") -> sáb | I21: =SUMIF(C:C,G21,D:D) -> 0 | K21: 18 | L21: =_xlfn.CONCAT(K21,"/",$L$1,"/",$L$2) -> 18/05/2026 | M21: =TEXT(L21,"ddd") -> seg | N21: =SUMIF(C:C,L21,D:D) -> 8095.87 | P21: 18 | Q21: =_xlfn.CONCAT(P21,"/",$Q$1,"/",$Q$2) -> 18/06/2026 | R21: =TEXT(Q21,"ddd") -> qui | S21: =SUMIF(C:C,Q21,D:D) -> 10963.14 | U21: 18 | V21: =_xlfn.CONCAT(U21,"/",$V$1,"/",$V$2) -> 18/07/2026 | W21: =TEXT(V21,"ddd") -> sáb | X21: =SUMIF(C:C,V21,D:D) -> 2068.47 | Z21: PM DE ARAPONGAS | AA21: 10247.68
A22: EMPRESA BRASILEIRA DE CORREIOS E TELEGRAFOS - ECT | B22: 1668551 | C22: 46147 | D22: 1546.09 | F22: 19 | G22: =_xlfn.CONCAT(F22,"/",$G$1,"/",$G$2) -> 19/04/2026 | H22: =TEXT(G22,"ddd") -> dom | I22: =SUMIF(C:C,G22,D:D) -> 0 | K22: 19 | L22: =_xlfn.CONCAT(K22,"/",$L$1,"/",$L$2) -> 19/05/2026 | M22: =TEXT(L22,"ddd") -> ter | N22: =SUMIF(C:C,L22,D:D) -> 19055.89 | P22: 19 | Q22: =_xlfn.CONCAT(P22,"/",$Q$1,"/",$Q$2) -> 19/06/2026 | R22: =TEXT(Q22,"ddd") -> sex | S22: =SUMIF(C:C,Q22,D:D) -> 2058.96 | U22: 19 | V22: =_xlfn.CONCAT(U22,"/",$V$1,"/",$V$2) -> 19/07/2026 | W22: =TEXT(V22,"ddd") -> dom | X22: =SUMIF(C:C,V22,D:D) -> 2058.96 | Z22: CEFAS S NOBRE | AA22: 31700
A23: COMPANY HERO LTDA | C23: 46147 | D23: 405.65 | F23: 20 | G23: =_xlfn.CONCAT(F23,"/",$G$1,"/",$G$2) -> 20/04/2026 | H23: =TEXT(G23,"ddd") -> seg | I23: =SUMIF(C:C,G23,D:D) -> 0 | K23: 20 | L23: =_xlfn.CONCAT(K23,"/",$L$1,"/",$L$2) -> 20/05/2026 | M23: =TEXT(L23,"ddd") -> qua | N23: =SUMIF(C:C,L23,D:D) -> 16446.17 | P23: 20 | Q23: =_xlfn.CONCAT(P23,"/",$Q$1,"/",$Q$2) -> 20/06/2026 | R23: =TEXT(Q23,"ddd") -> sáb | S23: =SUMIF(C:C,Q23,D:D) -> 27118.37 | U23: 20 | V23: =_xlfn.CONCAT(U23,"/",$V$1,"/",$V$2) -> 20/07/2026 | W23: =TEXT(V23,"ddd") -> seg | X23: =SUMIF(C:C,V23,D:D) -> 7978.87 | Z23: TOTAL A PAGAR DDA | AA23: 1754952.6
A24: TEK SYSTEM INFORMATICA LTDA | B24: 7883-CTR F | C24: 46147 | D24: 1046.56 | F24: 21 | G24: =_xlfn.CONCAT(F24,"/",$G$1,"/",$G$2) -> 21/04/2026 | H24: =TEXT(G24,"ddd") -> ter | I24: =SUMIF(C:C,G24,D:D) -> 0 | K24: 21 | L24: =_xlfn.CONCAT(K24,"/",$L$1,"/",$L$2) -> 21/05/2026 | M24: =TEXT(L24,"ddd") -> qui | N24: =SUMIF(C:C,L24,D:D) -> 52788.48 | P24: 21 | Q24: =_xlfn.CONCAT(P24,"/",$Q$1,"/",$Q$2) -> 21/06/2026 | R24: =TEXT(Q24,"ddd") -> dom | S24: =SUMIF(C:C,Q24,D:D) -> 3401.15 | U24: 21 | V24: =_xlfn.CONCAT(U24,"/",$V$1,"/",$V$2) -> 21/07/2026 | W24: =TEXT(V24,"ddd") -> ter | X24: =SUMIF(C:C,V24,D:D) -> 3401.12
A25: VEGA DISTRIBUIDORA LTDA | B25: 21002 | C25: 46148 | D25: 10284.72 | F25: 22 | G25: =_xlfn.CONCAT(F25,"/",$G$1,"/",$G$2) -> 22/04/2026 | H25: =TEXT(G25,"ddd") -> qua | I25: =SUMIF(C:C,G25,D:D) -> 0 | K25: 22 | L25: =_xlfn.CONCAT(K25,"/",$L$1,"/",$L$2) -> 22/05/2026 | M25: =TEXT(L25,"ddd") -> sex | N25: =SUMIF(C:C,L25,D:D) -> 5924.67 | P25: 22 | Q25: =_xlfn.CONCAT(P25,"/",$Q$1,"/",$Q$2) -> 22/06/2026 | R25: =TEXT(Q25,"ddd") -> seg | S25: =SUMIF(C:C,Q25,D:D) -> 29759.64 | U25: 22 | V25: =_xlfn.CONCAT(U25,"/",$V$1,"/",$V$2) -> 22/07/2026 | W25: =TEXT(V25,"ddd") -> qua | X25: =SUMIF(C:C,V25,D:D) -> 21888.98
A26: JULIO ANDO CIA LTDA | B26: 176776 1 | C26: 46148 | D26: 431.2 | F26: 23 | G26: =_xlfn.CONCAT(F26,"/",$G$1,"/",$G$2) -> 23/04/2026 | H26: =TEXT(G26,"ddd") -> qui | I26: =SUMIF(C:C,G26,D:D) -> 0 | K26: 23 | L26: =_xlfn.CONCAT(K26,"/",$L$1,"/",$L$2) -> 23/05/2026 | M26: =TEXT(L26,"ddd") -> sáb | N26: =SUMIF(C:C,L26,D:D) -> 46541.15 | P26: 23 | Q26: =_xlfn.CONCAT(P26,"/",$Q$1,"/",$Q$2) -> 23/06/2026 | R26: =TEXT(Q26,"ddd") -> ter | S26: =SUMIF(C:C,Q26,D:D) -> 35136.55 | U26: 23 | V26: =_xlfn.CONCAT(U26,"/",$V$1,"/",$V$2) -> 23/07/2026 | W26: =TEXT(V26,"ddd") -> qui | X26: =SUMIF(C:C,V26,D:D) -> 29929.84
A27: JULIO ANDO CIA LTDA | B27: 164999 4 | C27: 46149 | D27: 3024.7 | F27: 24 | G27: =_xlfn.CONCAT(F27,"/",$G$1,"/",$G$2) -> 24/04/2026 | H27: =TEXT(G27,"ddd") -> sex | I27: =SUMIF(C:C,G27,D:D) -> 0 | K27: 24 | L27: =_xlfn.CONCAT(K27,"/",$L$1,"/",$L$2) -> 24/05/2026 | M27: =TEXT(L27,"ddd") -> dom | N27: =SUMIF(C:C,L27,D:D) -> 27578.46 | P27: 24 | Q27: =_xlfn.CONCAT(P27,"/",$Q$1,"/",$Q$2) -> 24/06/2026 | R27: =TEXT(Q27,"ddd") -> qua | S27: =SUMIF(C:C,Q27,D:D) -> 12786 | U27: 24 | V27: =_xlfn.CONCAT(U27,"/",$V$1,"/",$V$2) -> 24/07/2026 | W27: =TEXT(V27,"ddd") -> sex | X27: =SUMIF(C:C,V27,D:D) -> 12786
A28: JULIO ANDO CIA LTDA | B28: 165093 4 | C28: 46149 | D28: 5968.71 | F28: 25 | G28: =_xlfn.CONCAT(F28,"/",$G$1,"/",$G$2) -> 25/04/2026 | H28: =TEXT(G28,"ddd") -> sáb | I28: =SUMIF(C:C,G28,D:D) -> 0 | K28: 25 | L28: =_xlfn.CONCAT(K28,"/",$L$1,"/",$L$2) -> 25/05/2026 | M28: =TEXT(L28,"ddd") -> seg | N28: =SUMIF(C:C,L28,D:D) -> 29002.69 | P28: 25 | Q28: =_xlfn.CONCAT(P28,"/",$Q$1,"/",$Q$2) -> 25/06/2026 | R28: =TEXT(Q28,"ddd") -> qui | S28: =SUMIF(C:C,Q28,D:D) -> 51193.3 | U28: 25 | V28: =_xlfn.CONCAT(U28,"/",$V$1,"/",$V$2) -> 25/07/2026 | W28: =TEXT(V28,"ddd") -> sáb | X28: =SUMIF(C:C,V28,D:D) -> 46632.72
A29: JULIO ANDO CIA LTDA | B29: 165074 4 | C29: 46149 | D29: 2299.91 | F29: 26 | G29: =_xlfn.CONCAT(F29,"/",$G$1,"/",$G$2) -> 26/04/2026 | H29: =TEXT(G29,"ddd") -> dom | I29: =SUMIF(C:C,G29,D:D) -> 0 | K29: 26 | L29: =_xlfn.CONCAT(K29,"/",$L$1,"/",$L$2) -> 26/05/2026 | M29: =TEXT(L29,"ddd") -> ter | N29: =SUMIF(C:C,L29,D:D) -> 44266.05 | P29: 26 | Q29: =_xlfn.CONCAT(P29,"/",$Q$1,"/",$Q$2) -> 26/06/2026 | R29: =TEXT(Q29,"ddd") -> sex | S29: =SUMIF(C:C,Q29,D:D) -> 13248.14 | U29: 26 | V29: =_xlfn.CONCAT(U29,"/",$V$1,"/",$V$2) -> 26/07/2026 | W29: =TEXT(V29,"ddd") -> dom | X29: =SUMIF(C:C,V29,D:D) -> 13248.16
A30: NEW BOX EMBALAGENS | B30: 30509 003 | C30: 46149 | D30: 2959.84 | F30: 27 | G30: =_xlfn.CONCAT(F30,"/",$G$1,"/",$G$2) -> 27/04/2026 | H30: =TEXT(G30,"ddd") -> seg | I30: =SUMIF(C:C,G30,D:D) -> 0 | K30: 27 | L30: =_xlfn.CONCAT(K30,"/",$L$1,"/",$L$2) -> 27/05/2026 | M30: =TEXT(L30,"ddd") -> qua | N30: =SUMIF(C:C,L30,D:D) -> 21244.07 | P30: 27 | Q30: =_xlfn.CONCAT(P30,"/",$Q$1,"/",$Q$2) -> 27/06/2026 | R30: =TEXT(Q30,"ddd") -> sáb | S30: =SUMIF(C:C,Q30,D:D) -> 53497.31 | U30: 27 | V30: =_xlfn.CONCAT(U30,"/",$V$1,"/",$V$2) -> 27/07/2026 | W30: =TEXT(V30,"ddd") -> seg | X30: =SUMIF(C:C,V30,D:D) -> 55604.06
A31: KALF IND COM PLASTICOS LTDA | B31: 123825 | C31: 46149 | D31: 582.13 | F31: 28 | G31: =_xlfn.CONCAT(F31,"/",$G$1,"/",$G$2) -> 28/04/2026 | H31: =TEXT(G31,"ddd") -> ter | I31: =SUMIF(C:C,G31,D:D) -> 0 | K31: 28 | L31: =_xlfn.CONCAT(K31,"/",$L$1,"/",$L$2) -> 28/05/2026 | M31: =TEXT(L31,"ddd") -> qui | N31: =SUMIF(C:C,L31,D:D) -> 53787.48 | P31: 28 | Q31: =_xlfn.CONCAT(P31,"/",$Q$1,"/",$Q$2) -> 28/06/2026 | R31: =TEXT(Q31,"ddd") -> dom | S31: =SUMIF(C:C,Q31,D:D) -> 10333.94 | U31: 28 | V31: =_xlfn.CONCAT(U31,"/",$V$1,"/",$V$2) -> 28/07/2026 | W31: =TEXT(V31,"ddd") -> ter | X31: =SUMIF(C:C,V31,D:D) -> 3906.74
A32: JULIO ANDO CIA LTDA | B32: 177140 1 | C32: 46149 | D32: 632.31 | F32: 29 | G32: =_xlfn.CONCAT(F32,"/",$G$1,"/",$G$2) -> 29/04/2026 | H32: =TEXT(G32,"ddd") -> qua | I32: =SUMIF(C:C,G32,D:D) -> 0 | K32: 29 | L32: =_xlfn.CONCAT(K32,"/",$L$1,"/",$L$2) -> 29/05/2026 | M32: =TEXT(L32,"ddd") -> sex | N32: =SUMIF(C:C,L32,D:D) -> 13798.54 | P32: 29 | Q32: =_xlfn.CONCAT(P32,"/",$Q$1,"/",$Q$2) -> 29/06/2026 | R32: =TEXT(Q32,"ddd") -> seg | S32: =SUMIF(C:C,Q32,D:D) -> 19284.55 | U32: 29 | V32: =_xlfn.CONCAT(U32,"/",$V$1,"/",$V$2) -> 29/07/2026 | W32: =TEXT(V32,"ddd") -> qua | X32: =SUMIF(C:C,V32,D:D) -> 12737.92
A33: NEW BOX EMBALAGENS | B33: 30926 001 | C33: 46149 | D33: 1775.9 | F33: 30 | G33: =_xlfn.CONCAT(F33,"/",$G$1,"/",$G$2) -> 30/04/2026 | H33: =TEXT(G33,"ddd") -> qui | I33: =SUMIF(C:C,G33,D:D) -> 0 | K33: 30 | L33: =_xlfn.CONCAT(K33,"/",$L$1,"/",$L$2) -> 30/05/2026 | M33: =TEXT(L33,"ddd") -> sáb | N33: =SUMIF(C:C,L33,D:D) -> 17177.8 | P33: 30 | Q33: =_xlfn.CONCAT(P33,"/",$Q$1,"/",$Q$2) -> 30/06/2026 | R33: =TEXT(Q33,"ddd") -> ter | S33: =SUMIF(C:C,Q33,D:D) -> 13434.05 | U33: 30 | V33: =_xlfn.CONCAT(U33,"/",$V$1,"/",$V$2) -> 30/07/2026 | W33: =TEXT(V33,"ddd") -> qui | X33: =SUMIF(C:C,V33,D:D) -> 13434.03
A34: BLUE CYCLE | B34: 403908 | C34: 46149 | D34: 2770.07 | F34: 31 | G34: =_xlfn.CONCAT(F34,"/",$G$1,"/",$G$2) -> 31/04/2026 | H34: =TEXT(G34,"ddd") -> 31/04/2026 | I34: =SUMIF(C:C,G34,D:D) -> 0 | K34: 31 | L34: =_xlfn.CONCAT(K34,"/",$L$1,"/",$L$2) -> 31/05/2026 | M34: =TEXT(L34,"ddd") -> dom | N34: =SUMIF(C:C,L34,D:D) -> 10030.29 | P34: 31 | Q34: =_xlfn.CONCAT(P34,"/",$Q$1,"/",$Q$2) -> 31/06/2026 | R34: =TEXT(Q34,"ddd") -> 31/06/2026 | S34: =SUMIF(C:C,Q34,D:D) -> 0 | U34: 31 | V34: =_xlfn.CONCAT(U34,"/",$V$1,"/",$V$2) -> 31/07/2026 | W34: =TEXT(V34,"ddd") -> sex | X34: =SUMIF(C:C,V34,D:D) -> 10842
A35: FMD -SECURITIZADORA S A | B35: 1324-001 | C35: 46149 | D35: 18093.31
A36: FLAY INDUSTRIA E COMERCIO LTDA | B36: 5237 - 1 | C36: 46149 | D36: 4288.74
A37: GRAFIMAX INDUSTRIA GRAFICA LTDA | B37: 1.28996-1/3 | C37: 46149 | D37: 1463.18
A38: EXCELLENCE TRANSP E LOGISTICA LTDA | B38: 3097455 | C38: 46149 | D38: 83.72
A39: NEW BIKE | B39: CJ714 001 | C39: 46149 | D39: 12247.5
A40: SPEED TECNET | B40: 700487653 | C40: 46149 | D40: 783.6
...

Sheet RECEBIDOS
A1: Banco | B1: Data | C1: Descrição | D1: Documento | E1: Valor (R$) | F1: Mktplace | H1: Mês | I1: Saldo | J1: Recebido Mês
A2: Sicredi | B2: 02/04/2026 | C2: RECEBIMENTO PIX 48697278000196 GOTT SAUDE COMERC | D2: PIX_CRED | E2: 20435 | H2: Abril | I2: 73659.53 | J2: =SUM(J4:J34) -> 883700.3 | L2: Mês de Competência | M2: Entradas | N2: Saídas | O2: Fluxo de Caixa
A3: Sicredi | B3: 06/04/2026 | C3: RECEBIMENTO PIX 48697278000196 GOTT SAUDE COMERC | D3: PIX_CRED | E3: 13502 | H3: Data | I3: Dia | J3: Recebido
A4: Sicredi | B4: 06/04/2026 | C4: GETNET CREDITO MASTER | GETNET | 0001-96 | D4: 819244258 | E4: 82.59 | H4: 46113 | I4: =H4 -> 46113 | J4: =SUMIF(B:B,H4,E:E) -> 0 | L4: =H2 -> Abril | M4: =J2 -> 883700.3 | N4: 851256.72 | O4: =M4-N4 -> 32443.58
A5: Sicredi | B5: 06/04/2026 | C5: RECEBIMENTO PIX 13884775000119 HUB INSTITUICAO D | D5: PIX_CRED | E5: 266.32 | H5: 46114 | I5: =H5 -> 46114 | J5: =SUMIF(B:B,H5,E:E) -> 20435 | M5: =M4/N14 -> 0.6874504
A6: Sicredi | B6: 06/04/2026 | C6: RECEBIMENTO PIX 48697278000196 GOTT SAUDE COMERC | D6: PIX_CRED | E6: 46650 | H6: 46115 | I6: =H6 -> 46115 | J6: =SUMIF(B:B,H6,E:E) -> 0
A7: Sicredi | B7: 07/04/2026 | C7: RECEBIMENTO PIX 27415911000136 Bytedance Brasil | D7: PIX_CRED | E7: 542.97 | H7: 46116 | I7: =H7 -> 46116 | J7: =SUMIF(B:B,H7,E:E) -> 0 | L7: =L2 -> Mês de Competência | M7: Saldo Inicial Conta | N7: Saldo Final Conta | O7: Fluxo de Conta
A8: Sicredi | B8: 07/04/2026 | C8: RECEBIMENTO PIX 48697278000196 GOTT SAUDE COMERC | D8: PIX_CRED | E8: 50000 | H8: 46117 | I8: =H8 -> 46117 | J8: =SUMIF(B:B,H8,E:E) -> 0
A9: Sicredi | B9: 08/04/2026 | C9: RECEBIMENTO PIX SICREDI 42965989000118 L A T SHO | D9: CX297608 | E9: 350 | H9: 46118 | I9: =H9 -> 46118 | J9: =SUMIF(B:B,H9,E:E) -> 60500.91 | L9: =L4 -> Abril | M9: 41217.95 | N9: =I2 -> 73659.53 | O9: =N9-M9 -> 32441.58
A10: Sicredi | B10: 08/04/2026 | C10: RECEBIMENTO PIX 48697278000196 GOTT SAUDE COMERC | D10: PIX_CRED | E10: 24769 | H10: 46119 | I10: =H10 -> 46119 | J10: =SUMIF(B:B,H10,E:E) -> 50542.97
A11: Sicredi | B11: 46121 | C11: TED 61074175000138 MAPFRE SEGUROS GERAIS S.A. | D11: 739614 | E11: 469.86 | H11: 46120 | I11: =H11 -> 46120 | J11: =SUMIF(B:B,H11,E:E) -> 25119
A12: Sicredi | B12: 46121 | C12: RECEBIMENTO PIX 48697278000196 GOTT SAUDE COMERC | D12: PIX_CRED | E12: 50000 | H12: 46121 | I12: =H12 -> 46121 | J12: =SUMIF(B:B,H12,E:E) -> 50469.86 | L12: =L7 -> Mês de Competência | M12: Meta Faturamento Bruto | N12: Faturamento Bruto | O12: Desempenho da Meta
A13: Sicredi | B13: 46122 | C13: GETNET CREDITO VISA | GETNET | 0001-96 | D13: 821732437 | E13: 2290.28 | H13: 46122 | I13: =H13 -> 46122 | J13: =SUMIF(B:B,H13,E:E) -> 8076.39
A14: Sicredi | B14: 46122 | C14: GETNET CREDITO ELO | GETNET | 0001-96 | D14: 821732411 | E14: 479.72 | H14: 46123 | I14: =H14 -> 46123 | J14: =SUMIF(B:B,H14,E:E) -> 0 | L14: =L9 -> Abril | M14: 1500000 | N14: 1285475 | O14: =N14/M14 -> 0.85698333
A15: Sicredi | B15: 46122 | C15: GETNET CREDITO MASTER | GETNET | 0001-96 | D15: 821732424 | E15: 2690.03 | H15: 46124 | I15: =H15 -> 46124 | J15: =SUMIF(B:B,H15,E:E) -> 0
A16: Sicredi | B16: 10/04/2026 | C16: RECEBIMENTO PIX 08584116000127 WEBCONTINENTAL LT | D16: PIX_CRED | E16: 2476.36 | H16: 46125 | I16: =H16 -> 46125 | J16: =SUMIF(B:B,H16,E:E) -> 52990.14 | L16: bikes | M16: 2130 | N16: 1667 | O16: =M16-N16 -> 463
A17: Sicredi | B17: 10/04/2026 | C17: RECEBIMENTO PIX 57436421000187 57.436.421 AUDINE | D17: PIX_CRED | E17: 140 | H17: 46126 | I17: =H17 -> 46126 | J17: =SUMIF(B:B,H17,E:E) -> 707.92
A18: Sicredi | B18: 13/04/2026 | C18: RECEBIMENTO PIX 48697278000196 GOTT SAUDE COMERC | D18: PIX_CRED | E18: 24850 | H18: 46127 | I18: =H18 -> 46127 | J18: =SUMIF(B:B,H18,E:E) -> 50000
A19: Sicredi | B19: 13/04/2026 | C19: RECEBIMENTO PIX 27415911000136 Bytedance Brasil | D19: PIX_CRED | E19: 256.14 | H19: 46128 | I19: =H19 -> 46128 | J19: =SUMIF(B:B,H19,E:E) -> 113089.92 | L19: Mês de Competência | M19: Entradas | N19: Saídas | O19: Fluxo de Caixa
A20: Sicredi | B20: 46125 | C20: RECEBIMENTO PIX 48697278000196 GOTT SAUDE COMERC | D20: PIX_CRED | E20: 27884 | H20: 46129 | I20: =H20 -> 46129 | J20: =SUMIF(B:B,H20,E:E) -> 42189 | L20: Março | M20: 1036116.5 | N20: 991713.58 | O20: 44402.94
A21: Sicredi | B21: 14/04/2026 | C21: RECEBIMENTO PIX 27415911000136 Bytedance Brasil | D21: PIX_CRED | E21: 707.92 | H21: 46130 | I21: =H21 -> 46130 | J21: =SUMIF(B:B,H21,E:E) -> 0
A22: Sicredi | B22: 46127 | C22: RECEBIMENTO PIX 48697278000196 GOTT SAUDE COMERC | D22: PIX_CRED | E22: 50000 | H22: 46131 | I22: =H22 -> 46131 | J22: =SUMIF(B:B,H22,E:E) -> 0
A23: Sicredi | B23: 46128 | C23: RECEBIMENTO PIX 48697278000196 GOTT SAUDE COMERC | D23: PIX_CRED | E23: 82039 | H23: 46132 | I23: =H23 -> 46132 | J23: =SUMIF(B:B,H23,E:E) -> 51153.36 | L23: Mês de Competência | M23: Saldo Inicial | N23: Saldo Final | O23: Fluxo de Conta
A24: Sicredi | B24: 46128 | C24: RECEBIMENTO PIX 48697278000196 GOTT SAUDE COMERC | D24: PIX_CRED | E24: 30409 | H24: 46133 | I24: =H24 -> 46133 | J24: =SUMIF(B:B,H24,E:E) -> 0 | L24: Março | M24: -3932.19 | N24: 41217.95 | O24: 45150.14
A25: Sicredi | B25: 46128 | C25: RECEBIMENTO PIX 27415911000136 Bytedance Brasil | D25: PIX_CRED | E25: 641.92 | H25: 46134 | I25: =H25 -> 46134 | J25: =SUMIF(B:B,H25,E:E) -> 141158.12
A26: Sicredi | B26: 17/04/2026 | C26: RECEBIMENTO PIX 48697278000196 GOTT SAUDE COMERC | D26: PIX_CRED | E26: 42189 | H26: 46135 | I26: =H26 -> 46135 | J26: =SUMIF(B:B,H26,E:E) -> 54913
A27: Sicredi | B27: 46132 | C27: GETNET CREDITO VISA | GETNET | 0001-96 | D27: 825395361 | E27: 5771.86 | H27: 46136 | I27: =H27 -> 46136 | J27: =SUMIF(B:B,H27,E:E) -> 40462
A28: Sicredi | B28: 46132 | C28: GETNET CREDITO ELO | GETNET | 0001-96 | D28: 825395626 | E28: 751.55 | H28: 46137 | I28: =H28 -> 46137 | J28: =SUMIF(B:B,H28,E:E) -> 0
A29: Sicredi | B29: 46132 | C29: GETNET CREDITO MASTER | GETNET | 0001-96 | D29: 825395623 | E29: 8083.68 | H29: 46138 | I29: =H29 -> 46138 | J29: =SUMIF(B:B,H29,E:E) -> 0
A30: Sicredi | B30: 46132 | C30: GETNET CREDITO MASTER | GETNET | 0001-96 | D30: 825395350 | E30: 1312.2 | H30: 46139 | I30: =H30 -> 46139 | J30: =SUMIF(B:B,H30,E:E) -> 14676.54
A31: Sicredi | B31: 46132 | C31: GETNET CREDITO VISA | GETNET | 0001-96 | D31: 825395662 | E31: 678.51 | H31: 46140 | I31: =H31 -> 46140 | J31: =SUMIF(B:B,H31,E:E) -> 71423
A32: Sicredi | B32: 46132 | C32: GETNET CREDITO MASTER | GETNET | 0001-96 | D32: 825395646 | E32: 616.95 | H32: 46141 | I32: =H32 -> 46141 | J32: =SUMIF(B:B,H32,E:E) -> 33906.17
A33: Sicredi | B33: 46132 | C33: GETNET CREDITO AMEX | GETNET | 0001-96 | D33: 825395374 | E33: 553.13 | H33: 46142 | I33: =H33 -> 46142 | J33: =SUMIF(B:B,H33,E:E) -> 1887
A34: Sicredi | B34: 20/04/2026 | C34: RECEBIMENTO PIX 13884775000119 HUB INSTITUICAO D | D34: PIX_CRED | E34: 1451.48 | I34: =H34 -> 0 | J34: =SUMIF(B:B,H34,E:E) -> 0
A35: Sicredi | B35: 20/04/2026 | C35: RECEBIMENTO PIX 48697278000196 GOTT SAUDE COMERC | D35: PIX_CRED | E35: 31934
A36: Sicredi | B36: 46134 | C36: TED 33041260065290 GRUPO CASAS BAHIA S A | D36: 459370 | E36: 81158.12
A37: Sicredi | B37: 46134 | C37: RECEBIMENTO PIX 48697278000196 GOTT SAUDE COMERC | D37: PIX_CRED | E37: 50000
A38: Sicredi | B38: 46134 | C38: RECEBIMENTO PIX 48697278000196 GOTT SAUDE COMERC | D38: PIX_CRED | E38: 10000
A39: Sicredi | B39: 46135 | C39: RECEBIMENTO PIX 48697278000196 GOTT SAUDE COMERC | D39: PIX_CRED | E39: 4563
A40: Sicredi | B40: 46135 | C40: RECEBIMENTO PIX 45990586000117 TAC STORE | D40: PIX_CRED | E40: 350 | L40: Meta do Mês de abr/26
...

Sheet COMPARATIVOS
B1: jan | C1: fev | D1: mar | E1: abr | F1: mai | G1: jun | H1: jul | I1: ago | J1: set | K1: out | L1: nov | M1: dez
A2: FATURAMENTO BRUTO 2025 | B2: 189017.45 | C2: 275579.51 | D2: 964961.41 | E2: 583899.22 | F2: 662010.94 | G2: 885159.23 | H2: 868491.23 | I2: 885285.93 | J2: 1150688.3 | K2: 1207207 | L2: 1594226.2 | M2: 1443037.2
A3: FATURAMENTO BRUTO 2026 | B3: 1101552 | C3: 936890.74 | D3: 1373580.8
A4: VARIAÇÃO 26X25 | B4: =IFERROR(B3/B2-1,0) -> 4.8277795 | C4: =IFERROR(C3/C2-1,0) -> 2.3997112 | D4: =IFERROR(D3/D2-1,0) -> 0.42345673
B24: jan | C24: fev | D24: mar | E24: abr | F24: mai | G24: jun | H24: jul | I24: ago | J24: set | K24: out | L24: nov | M24: dez
A25: BIKES FATURADAS 2025 | B25: 282 | C25: 471 | D25: 1435 | E25: 814 | F25: 921 | G25: 1142 | H25: 1313 | I25: 1291 | J25: 1765 | K25: 1825 | L25: 2268 | M25: 2185
A26: BIKES FATURADAS 2026 | B26: 1647 | C26: 1330 | D26: 1877
A27: VARIAÇÃO 26X25 | B27: =IFERROR(B26/B25-1,0) -> 4.8404255 | C27: =IFERROR(C26/C25-1,0) -> 1.8237792 | D27: =IFERROR(D26/D25-1,0) -> 0.30801394
B47: out/25 | D47: nov/25 | F47: dez/25 | H47: jan/26 | J47: 46054
B48: R$ | C48: A.V. | D48: R$ | E48: A.V. | F48: R$ | G48: A.V. | H48: R$ | I48: A.V. | J48: R$ | K48: A.V.
A49: TOTAL FATURADO | B49: =SUM(B50:B59) -> 1137554.1 | C49: =IFERROR(B49/$H$49,0) -> 1.0363134 | D49: =SUM(D50:D59) -> 1453565.2 | E49: =IFERROR(D49/$H$49,0) -> 1.3242 | F49: =SUM(F50:F59) -> 1358251.7 | G49: =IFERROR(F49/$H$49,0) -> 1.2373692 | H49: =SUM(H50:H59) -> 1097693.1 | I49: =IFERROR(H49/$H$49,0) -> 1 | J49: =SUM(J50:J59) -> 936890.74 | K49: =IFERROR(J49/$J$49,0) -> 1
A50: SHOPEE | B50: 710617.19 | C50: =IFERROR(B50/$H$49,0) -> 0.64737327 | D50: 1003857.3 | E50: =IFERROR(D50/$H$49,0) -> 0.91451542 | F50: 1143229.9 | G50: =IFERROR(F50/$H$49,0) -> 1.041484 | H50: 878335.15 | I50: =IFERROR(H50/$H$49,0) -> 0.80016457 | J50: 815488.19 | K50: =IFERROR(J50/$J$49,0) -> 0.87041974 | L50: 777103.83 | M50: -45599.04 | N50: 50000 | O50: 781504.79
A51: AMAZON | B51: 1538 | C51: =IFERROR(B51/$H$49,0) -> 0.0014011202 | D51: 2117 | E51: =IFERROR(D51/$H$49,0) -> 0.00192859 | G51: =IFERROR(F51/$H$49,0) -> 0 | H51: 0 | I51: =IFERROR(H51/$H$49,0) -> 0 | J51: 2696 | K51: =IFERROR(J51/$J$49,0) -> 0.0028776034
A52: MAGALU | B52: 82235.32 | C52: =IFERROR(B52/$H$49,0) -> 0.074916493 | D52: 124166.39 | E52: =IFERROR(D52/$H$49,0) -> 0.11311576 | F52: 35919.19 | G52: =IFERROR(F52/$H$49,0) -> 0.032722433 | H52: 19002.9 | I52: =IFERROR(H52/$H$49,0) -> 0.017311669 | J52: 8376.37 | K52: =IFERROR(J52/$J$49,0) -> 0.008940605
A53: MELI | B53: 315559.54 | C53: =IFERROR(B53/$H$49,0) -> 0.28747519 | D53: 210466.92 | E53: =IFERROR(D53/$H$49,0) -> 0.19173566 | F53: 44802.23 | G53: =IFERROR(F53/$H$49,0) -> 0.040814895 | H53: 46735.55 | I53: =IFERROR(H53/$H$49,0) -> 0.042576152 | J53: 11496.08 | K53: =IFERROR(J53/$J$49,0) -> 0.01227046
A54: NETSHOES | B54: 2493.1 | C54: =IFERROR(B54/$H$49,0) -> 0.0022712176 | D54: 2050.05 | E54: =IFERROR(D54/$H$49,0) -> 0.0018675985 | F54: 2024.1 | G54: =IFERROR(F54/$H$49,0) -> 0.001843958 | H54: 1532 | I54: =IFERROR(H54/$H$49,0) -> 0.0013956542 | J54: 2567 | K54: =IFERROR(J54/$J$49,0) -> 0.0027399139 | L54: Janeiro | O54: Janeiro
A55: TIKTOK | C55: =IFERROR(B55/$H$49,0) -> 0 | E55: =IFERROR(D55/$H$49,0) -> 0 | F55: 2626 | G55: =IFERROR(F55/$H$49,0) -> 0.0023922897 | H55: 3270 | I55: =IFERROR(H55/$H$49,0) -> 0.0029789746 | J55: 4619.3 | K55: =IFERROR(J55/$J$49,0) -> 0.0049304575 | L55: Carnê Digital / Cartão de Crédito | O55: Pix / Cartão Presente / Nubank
A56: VIA VAREJO | B56: 17303.1 | C56: =IFERROR(B56/$H$49,0) -> 0.015763149 | D56: 105336.25 | E56: =IFERROR(D56/$H$49,0) -> 0.095961473 | F56: 126380.2 | G56: =IFERROR(F56/$H$49,0) -> 0.11513254 | H56: 143471.63 | I56: =IFERROR(H56/$H$49,0) -> 0.13070286 | J56: 87751.8 | K56: =IFERROR(J56/$J$49,0) -> 0.093662789 | L56: 99100 | M56: 83200 | O56: 59321 | P56: 49830
A57: NEXTSHOP | C57: =IFERROR(B57/$H$49,0) -> 0 | E57: =IFERROR(D57/$H$49,0) -> 0 | G57: =IFERROR(F57/$H$49,0) -> 0 | H57: 1399 | I57: =IFERROR(H57/$H$49,0) -> 0.001274491 | J57: 0 | K57: =IFERROR(J57/$J$49,0) -> 0
A58: WEB CONTINENTAL | B58: 7807.88 | C58: =IFERROR(B58/$H$49,0) -> 0.0071129898 | D58: 5571.35 | E58: =IFERROR(D58/$H$49,0) -> 0.0050755078 | F58: 1672.08 | G58: =IFERROR(F58/$H$49,0) -> 0.0015232673 | H58: 3946.9 | I58: =IFERROR(H58/$H$49,0) -> 0.0035956315 | J58: 3896 | K58: =IFERROR(J58/$J$49,0) -> 0.0041584358
A59: CENTAURO | C59: =IFERROR(B59/$H$49,0) -> 0 | E59: =IFERROR(D59/$H$49,0) -> 0 | F59: 1598 | G59: =IFERROR(F59/$H$49,0) -> 0.0014557803 | I59: =IFERROR(H59/$H$49,0) -> 0 | K59: =IFERROR(J59/$J$49,0) -> 0
B61: out/25 | D61: nov/25 | F61: dez/25 | H61: jan/26 | J61: 46054
B62: R$ | C62: A.V. | D62: R$ | E62: A.V. | F62: R$ | G62: A.V. | H62: R$ | I62: A.V. | J62: R$ | K62: A.V.
A63: TOTAL RECEBIDO | B63: =SUM(B64:B72) -> 1051608.4 | C63: =IFERROR(B63/$H$49,0) -> 0.95801673 | D63: =SUM(D64:D72) -> 881367.09 | E63: =IFERROR(D63/$H$49,0) -> 0.80292667 | F63: =SUM(F64:F72) -> 1057975.4 | G63: =IFERROR(F63/$H$49,0) -> 0.96381713 | H63: =SUM(H64:H72) -> 872469.19 | I63: =IFERROR(H63/$H$63,0) -> 1 | J63: =SUM(J64:J72) -> 678773.05 | K63: =IFERROR(J63/$J$63,0) -> 1 | M63: =J49-J63 -> 258117.69
A64: SHOPEE | B64: 573515.5 | C64: =IFERROR(B64/$B$63,0) -> 0.54536985 | D64: 619369.09 | E64: =IFERROR(D64/$D$63,0) -> 0.7027368 | F64: 977743.02 | G64: =IFERROR(F64/$F$63,0) -> 0.92416419 | H64: 777103.83 | I64: =IFERROR(H64/$H$63,0) -> 0.89069487 | J64: 597013 | K64: =IFERROR(J64/$J$63,0) -> 0.87954729
A65: AMAZON | C65: =IFERROR(B65/$B$63,0) -> 0 | E65: =IFERROR(D65/$D$63,0) -> 0 | G65: =IFERROR(F65/$F$63,0) -> 0 | H65: 0 | I65: =IFERROR(H65/$H$63,0) -> 0 | J65: 0 | K65: =IFERROR(J65/$J$63,0) -> 0
A66: MAGALU | B66: 54734.07 | C66: =IFERROR(B66/$B$63,0) -> 0.052047959 | D66: 93530.54 | E66: =IFERROR(D66/$D$63,0) -> 0.10611985 | F66: 25250.5 | G66: =IFERROR(F66/$F$63,0) -> 0.023866811 | H66: 22805.34 | I66: =IFERROR(H66/$H$63,0) -> 0.026138849 | J66: 26055.41 | K66: =IFERROR(J66/$J$63,0) -> 0.038386041
A67: MELI | B67: 397000 | C67: =IFERROR(B67/$B$63,0) -> 0.37751696 | D67: 156210 | E67: =IFERROR(D67/$D$63,0) -> 0.17723603 | F67: 49400 | G67: =IFERROR(F67/$F$63,0) -> 0.046692955 | H67: 33580.54 | I67: =IFERROR(H67/$H$63,0) -> 0.038489084 | J67: 0 | K67: =IFERROR(J67/$J$63,0) -> 0
A68: NETSHOES | B68: 620.59 | C68: =IFERROR(B68/$B$63,0) -> 0.00059013413 | E68: =IFERROR(D68/$D$63,0) -> 0 | F68: 4.46 | G68: =IFERROR(F68/$F$63,0) -> 4.2155988e-06 | H68: 0 | I68: =IFERROR(H68/$H$63,0) -> 0 | J68: 0 | K68: =IFERROR(J68/$J$63,0) -> 0
A69: TIKTOK | C69: =IFERROR(B69/$B$63,0) -> 0 | E69: =IFERROR(D69/$D$63,0) -> 0 | G69: =IFERROR(F69/$F$63,0) -> 0 | H69: 0 | I69: =IFERROR(H69/$H$63,0) -> 0 | J69: 5164.94 | K69: =IFERROR(J69/$J$63,0) -> 0.0076092296
A70: VIA VAREJO | B70: 25738.22 | C70: =IFERROR(B70/$B$63,0) -> 0.0244751 | D70: 10160.24 | E70: =IFERROR(D70/$D$63,0) -> 0.011527819 | F70: 2877.48 | G70: =IFERROR(F70/$F$63,0) -> 0.0027197985 | H70: 37472.77 | I70: =IFERROR(H70/$H$63,0) -> 0.04295025 | J70: 50103.94 | K70: =IFERROR(J70/$J$63,0) -> 0.073815453
A71: NEXTSHOP | C71: =IFERROR(B71/$B$63,0) -> 0 | E71: =IFERROR(D71/$D$63,0) -> 0 | G71: =IFERROR(F71/$F$63,0) -> 0 | H71: 0 | I71: =IFERROR(H71/$H$63,0) -> 0 | J71: 0 | K71: =IFERROR(J71/$J$63,0) -> 0
A72: WEB CONTINENTAL | C72: =IFERROR(B72/$B$63,0) -> 0 | D72: 2097.22 | E72: =IFERROR(D72/$D$63,0) -> 0.002379508 | F72: 2699.98 | G72: =IFERROR(F72/$F$63,0) -> 0.0025520252 | H72: 1506.71 | I72: =IFERROR(H72/$H$63,0) -> 0.0017269492 | J72: 435.76 | K72: =IFERROR(J72/$J$63,0) -> 0.00064198188
A73: CENTAURO | C73: =IFERROR(B73/$B$63,0) -> 0 | E73: =IFERROR(D73/$D$63,0) -> 0 | G73: =IFERROR(F73/$F$63,0) -> 0 | I73: =IFERROR(H73/$H$63,0) -> 0 | K73: =IFERROR(J73/$J$49,0) -> 0
B75: out/25 | D75: nov/25 | F75: dez/25 | H75: jan/26 | J75: 46054
A76: % RECEBIDO | B76: =IFERROR(B63/B49,0) -> 0.92444689 | D76: =IFERROR(D63/D49,0) -> 0.60634849 | F76: =IFERROR(F63/F49,0) -> 0.77892445 | H76: =IFERROR(H63/H49,0) -> 0.79482067 | J76: =IFERROR(J63/J49,0) -> 0.72449542
A77: SHOPEE | B77: =IFERROR(B64/B50,0) -> 0.80706674 | D77: =IFERROR(D64/D50,0) -> 0.61698918 | F77: =IFERROR(F64/F50,0) -> 0.85524622 | H77: =IFERROR(H64/H50,0) -> 0.88474636 | J77: =IFERROR(J64/J50,0) -> 0.73209276
A78: AMAZON | B78: =IFERROR(B65/B51,0) -> 0 | D78: =IFERROR(D65/D51,0) -> 0 | F78: =IFERROR(F65/F51,0) -> 0 | H78: =IFERROR(H65/H51,0) -> 0 | J78: =IFERROR(J65/J51,0) -> 0
A79: MAGALU | B79: =IFERROR(B66/B52,0) -> 0.66557861 | D79: =IFERROR(D66/D52,0) -> 0.75326777 | F79: =IFERROR(F66/F52,0) -> 0.70298077 | H79: =IFERROR(H66/H52,0) -> 1.2000979 | J79: =IFERROR(J66/J52,0) -> 3.1105849
A80: MELI | B80: =IFERROR(B67/B53,0) -> 1.2580827 | D80: =IFERROR(D67/D53,0) -> 0.7422069 | F80: =IFERROR(F67/F53,0) -> 1.1026237 | H80: =IFERROR(H67/H53,0) -> 0.71852241 | J80: =IFERROR(J67/J53,0) -> 0
...

Sheet FATURAS
B2: VCTO | C2: DESCRIÇÃO | D2: VALOR | E2: CLASSIFICAÇÃO | G2: VCTO | H2: (Tudo)
B3: 46066 | C3: Shopee | D3: 1500 | E3: ADS SHOPEE
B4: 46066 | C4: Shopee | D4: 1500 | E4: ADS SHOPEE | G4: CLASSIFICAÇÃO | H4: Soma de VALOR
B5: 46066 | C5: Shopee | D5: 1800 | E5: ADS SHOPEE | G5: ADS MAGALU | H5: 5200
B6: 46066 | C6: Shopee | D6: 1800 | E6: ADS SHOPEE | G6: ADS SHOPEE | H6: 39900
B7: 46066 | C7: Churrascaria Herança | D7: 641 | E7: ALIMENTAÇÃO | G7: ALIMENTAÇÃO | H7: 7604.21
B8: 46066 | C8: Padaria Chij | D8: 23 | E8: ALIMENTAÇÃO | G8: ASSINATURAS | H8: 13165.6
B9: 46066 | C9: Restaurante Abençoado | D9: 69.27 | E9: ALIMENTAÇÃO | G9: COMBUSTÍVEL | H9: 2929.73
B10: 46066 | C10: Adobe | D10: 169 | E10: ASSINATURAS | G10: COMISSÕES E TAXAS DOS MARKETPLACES | H10: 5269.82
B11: 46066 | C11: BR1 China Lin Do Brasil | D11: 1600 | E11: ASSINATURAS | G11: COMPRA DE MÓVEIS E UTENSÍLIOS | H11: 552.41
B12: 46066 | C12: Pro TeamViewer (Parc 2/10) | D12: 58.8 | E12: ASSINATURAS | G12: DESP DE MARKETING E PROPAGANDA | H12: 1305
B13: 46066 | C13: Sem Parar | D13: 64.7 | E13: ASSINATURAS | G13: DESPESAS DE VIAGEM | H13: 16647.49
B14: 46066 | C14: Vindi Tray Ecommerce (Parc 4/6) | D14: 269.99 | E14: ASSINATURAS | G14: DESPESAS MANUTENCAO VEICULOS | H14: 3411.06
B15: 46066 | C15: Auto Posto Verona | D15: 340.54 | E15: COMBUSTÍVEL | G15: ESTACIONAMENTO | H15: 639
B16: 46066 | C16: Malassise Ribeirete | D16: 187.98 | E16: COMBUSTÍVEL | G16: FERRAMENTAS PARA MANUTENÇÃO | H16: 5109
... B24: 46066 | C24: Hotel San Gabriel | D24: 772 | E24: DESPESAS DE VIAGEM | G24: Total Geral | H24: 200228.59
B25: 46066 | C25: Rancho do Tiothor | D25: 51.97 | E25: DESPESAS DE VIAGEM
B26: 46066 | C26: Rodo Stop | D26: 23.1 | E26: DESPESAS DE VIAGEM
B27: 46066 | C27: Uber | D27: 45.97 | E27: DESPESAS DE VIAGEM
B28: 46066 | C28: Uber | D28: 27.98 | E28: DESPESAS DE VIAGEM
B29: 46066 | C29: Uber | D29: 115 | E29: DESPESAS DE VIAGEM
B30: 46066 | C30: Uber (pendente) | D30: 35.98 | E30: DESPESAS DE VIAGEM
B31: 46066 | C31: Villa Country | D31: 210 | E31: DESPESAS DE VIAGEM
B32: 46066 | C32: MP Motortech (Parc 2/3) | D32: 1705.52 | E32: DESPESAS MANUTENCAO VEICULOS
B33: 46066 | C33: DR Comércio de Tintas | D33: 759 | E33: FERRAMENTAS PARA MANUTENÇÃO
B34: 46066 | C34: Superfer Comercial | D34: 2175 | E34: FERRAMENTAS PARA MANUTENÇÃO
B35: 46066 | C35: Keb Continental (Virtual) | D35: 35 | E35: OUTRAS DESPESAS ADMINISTRATIVAS
B36: 46066 | C36: MercadoLivre | D36: 54.55 | E36: OUTRAS DESPESAS ADMINISTRATIVAS
... B282: 46094 | C282: Vindi Trayecommer | D282: 269.99 | E282: ASSINATURAS

Sheet MÉTRICAS
B1: DEMONSTARATIVO DE RESULTADOS GOTT | C1: 45931 | D1: 45962 | E1: 45992 | F1: 46023 | G1: 46054 | H1: 46082
A2: Gráfico linha | B2: =DRE!B3 -> (+) FATURAMENTO BRUTO | C2: =DRE!C3 -> 1207207 | D2: =DRE!E3 -> 1594226.2 | E2: =DRE!H3 -> 1443037.2 | F2: =DRE!K3 -> 1101552 | G2: =DRE!N3 -> 936890.74 | H2: =DRE!Q3 -> 1373580.8
A3: Gráfico coluna | B3: =DRE!B3 -> (+) FATURAMENTO BRUTO | C3: =IFERROR(C2/C2,0) -> 1 | D3: =IFERROR(D2/D2,0) -> 1 | E3: =IFERROR(E2/E2,0) -> 1 | F3: =IFERROR(F2/F2,0) -> 1 | G3: =IFERROR(G2/G2,0) -> 1 | H3: =IFERROR(H2/H2,0) -> 1
A5: Gráfico linha | B5: =DRE!B4 -> (-) IMPOSTOS S/ VENDAS | C5: =DRE!C4 -> 35650.83 | D5: =DRE!E4 -> 21104.11 | E5: =DRE!H4 -> 19335 | F5: =DRE!K4 -> 15811.61 | G5: =DRE!N4 -> 14053.361 | H5: =DRE!Q4 -> 29702.17
A6: Gráfico coluna | B6: =DRE!B4 -> (-) IMPOSTOS S/ VENDAS | C6: =IFERROR(C5/C2,0) -> 0.029531663 | D6: =IFERROR(D5/D2,0) -> 0.013237839 | E6: =IFERROR(E5/E2,0) -> 0.013398823 | F6: =IFERROR(F5/F2,0) -> 0.014353939 | G6: =IFERROR(G5/G2,0) -> 0.015 | H6: =IFERROR(H5/H2,0) -> 0.021623897
A8: Gráfico linha | B8: =DRE!B5 -> (-) DEVOLUÇÕES | C8: =DRE!C5 -> 0 | D8: =DRE!E5 -> 0 | E8: =DRE!H5 -> 0 | F8: =DRE!K5 -> 0 | G8: =DRE!N5 -> 0 | H8: =DRE!Q5 -> 0
A9: Gráfico coluna | B9: =DRE!B5 -> (-) DEVOLUÇÕES | C9: =IFERROR(C8/C2,0) -> 0 | D9: =IFERROR(D8/D2,0) -> 0 | E9: =IFERROR(E8/E2,0) -> 0 | F9: =IFERROR(F8/F2,0) -> 0 | G9: =IFERROR(G8/G2,0) -> 0 | H9: =IFERROR(H8/H2,0) -> 0
A11: Gráfico linha | B11: =DRE!B6 -> (-) DESPESAS COM TRANSPORTE | C11: =DRE!C6 -> 9199.86 | D11: =DRE!E6 -> 1174.88 | E11: =DRE!H6 -> 6687.27 | F11: =DRE!K6 -> 20376.21 | G11: =DRE!N6 -> 31195.07 | H11: =DRE!Q6 -> 23710.91
A12: Gráfico coluna | B12: =DRE!B6 -> (-) DESPESAS COM TRANSPORTE | C12: =IFERROR(C11/C2,0) -> 0.0076207809 | D12: =IFERROR(D11/D2,0) -> 0.00073695939 | E12: =IFERROR(E11/E2,0) -> 0.0046341633 | F12: =IFERROR(F11/F2,0) -> 0.018497728 | G12: =IFERROR(G11/G2,0) -> 0.03329638 | H12: =IFERROR(H11/H2,0) -> 0.017262115
A14: Gráfico linha | B14: =DRE!B10 -> (-) RECEITA OPERACIONAL LÍQUIDA | C14: =DRE!C10 -> 1162356.3 | D14: =DRE!E10 -> 1571947.2 | E14: =DRE!H10 -> 1417014.9 | F14: =DRE!K10 -> 1065364.2 | G14: =DRE!N10 -> 891642.31 | H14: =DRE!Q10 -> 1320167.7
A15: Gráfico coluna | B15: =DRE!B10 -> (-) RECEITA OPERACIONAL LÍQUIDA | C15: =IFERROR(C14/C2,0) -> 0.96284756 | D15: =IFERROR(D14/D2,0) -> 0.9860252 | E15: =IFERROR(E14/E2,0) -> 0.98196701 | F15: =IFERROR(F14/F2,0) -> 0.96714833 | G15: =IFERROR(G14/G2,0) -> 0.95170362 | H15: =IFERROR(H14/H2,0) -> 0.96111399
A17: Gráfico linha | B17: =DRE!B11 -> (-) CUSTOS VARIÁVEIS OPERACIONAIS | C17: =DRE!C11 -> 923317.34 | D17: =DRE!E11 -> 1282104.1 | E17: =DRE!H11 -> 1119132.4 | F17: =DRE!K11 -> 865095.17 | G17: =DRE!N11 -> 755745.51 | H17: =DRE!Q11 -> 1074369.7
A18: Gráfico coluna | B18: =DRE!B11 -> (-) CUSTOS VARIÁVEIS OPERACIONAIS | C18: =IFERROR(C17/C2,0) -> 0.76483764 | D18: =IFERROR(D17/D2,0) -> 0.80421716 | E18: =IFERROR(E17/E2,0) -> 0.77553956 | F18: =IFERROR(F17/F2,0) -> 0.7853421 | G18: =IFERROR(G17/G2,0) -> 0.80665277 | H18: =IFERROR(H17/H2,0) -> 0.7821671
A20: Gráfico linha | B20: =DRE!B12 -> (-) CUSTO DOS PRODUTOS VENDIDOS | C20: =DRE!C12 -> 707593.72 | D20: =DRE!E12 -> 998625.2 | E20: =DRE!H12 -> 857572.81 | F20: =DRE!K12 -> 667576.62 | G20: =DRE!N12 -> 577935.69 | H20: =DRE!Q12 -> 817037.46
A21: Gráfico coluna | B21: =DRE!B12 -> (-) CUSTO DOS PRODUTOS VENDIDOS | C21: =IFERROR(C20/C2,0) -> 0.58614117 | D21: =IFERROR(D20/D2,0) -> 0.62640118 | E21: =IFERROR(E20/E2,0) -> 0.59428323 | F21: =IFERROR(F20/F2,0) -> 0.60603277 | G21: =IFERROR(G20/G2,0) -> 0.61686562 | H21: =IFERROR(H20/H2,0) -> 0.594823
A23: Gráfico linha | B23: =DRE!B13 -> (-) DESPESAS DE VENDA | C23: =DRE!C13 -> 215723.62 | D23: =DRE!E13 -> 283478.89 | E23: =DRE!H13 -> 261559.62 | F23: =DRE!K13 -> 197518.55 | G23: =DRE!N13 -> 177809.82 | H23: =DRE!Q13 -> 257332.26
A24: Gráfico coluna | B24: =DRE!B13 -> (-) DESPESAS DE VENDA | C24: =IFERROR(C23/C2,0) -> 0.17869647 | D24: =IFERROR(D23/D2,0) -> 0.17781597 | E24: =IFERROR(E23/E2,0) -> 0.18125633 | F24: =IFERROR(F23/F2,0) -> 0.17930933 | G24: =IFERROR(G23/G2,0) -> 0.18978715 | H24: =IFERROR(H23/H2,0) -> 0.1873441
A26: Gráfico linha | B26: =DRE!B21 -> (=) MARGEM DE CONTRIBUIÇÃO | C26: =DRE!C21 -> 239038.96 | D26: =DRE!E21 -> 289843.16 | E26: =DRE!H21 -> 297882.5 | F26: =DRE!K21 -> 200269.03 | G26: =DRE!N21 -> 135896.8 | H26: =DRE!Q21 -> 245798.01
A27: Gráfico coluna | B27: =DRE!B21 -> (=) MARGEM DE CONTRIBUIÇÃO | C27: =IFERROR(C26/C2,0) -> 0.19800992 | D27: =IFERROR(D26/D2,0) -> 0.18180805 | E27: =IFERROR(E26/E2,0) -> 0.20642746 | F27: =IFERROR(F26/F2,0) -> 0.18180624 | G27: =IFERROR(G26/G2,0) -> 0.14505085 | H27: =IFERROR(H26/H2,0) -> 0.17894689
A29: Gráfico linha | B29: =DRE!B22 -> (-) CUSTOS FIXOS OPERACIONAIS | C29: =DRE!C22 -> 93406.07 | D29: =DRE!E22 -> 104939.41 | E29: =DRE!H22 -> 108655.94 | F29: =DRE!K22 -> 119972.84 | G29: =DRE!N22 -> 119526.37 | H29: =DRE!Q22 -> 138043.59
A30: Gráfico coluna | B30: =DRE!B22 -> (-) CUSTOS FIXOS OPERACIONAIS | C30: =IFERROR(C29/C2,0) -> 0.077373699 | D30: =IFERROR(D29/D2,0) -> 0.065824666 | E30: =IFERROR(E29/E2,0) -> 0.075296701 | F30: =IFERROR(F29/F2,0) -> 0.10891255 | G30: =IFERROR(G29/G2,0) -> 0.1275777 | H30: =IFERROR(H29/H2,0) -> 0.10049907
A32: Gráfico linha | B32: =DRE!B23 -> (=) RESULTADO OPERACIONAL | C32: =DRE!C23 -> 145632.89 | D32: =DRE!E23 -> 184903.75 | E32: =DRE!H23 -> 189226.56 | F32: =DRE!K23 -> 80296.186 | G32: =DRE!N23 -> 16370.429 | H32: =DRE!Q23 -> 107754.42
